Workbook

Sheet Оглавление
A1: 2023-2026 гг, | B1: Голышмановский муниципальный округ | C1: До 2025 г - Голышмановский городской округ
B2: Показатели, характеризующие состояние экономики и социальной сферы муниципального образования
A3: Лист | B3: Таблица с данными | C3: Кол-во показателей | D3: 2023 | E3: 2024 | F3: 2025 | G3: 2026
A4: 1 | B4: Платные услуги населению | C4: =COUNTA('1'!C$3:F$5000) -> 0 | D4: 0 | E4: 0 | F4: =COUNTA('1'!C$3:C$5000) -> 0 | G4: =COUNTA('1'!D$3:D$5000) -> 0
A5: 2 | B5: Розничная торговля и общественное питание | C5: =COUNTA('2'!C$3:F$5000) -> 55 | D5: 0 | E5: 0 | F5: =COUNTA('2'!C$3:C$5000) -> 55 | G5: =COUNTA('2'!D$3:D$5000) -> 0
A6: 3 | B6: Спорт | C6: =COUNTA('3'!C$3:F$5000) -> 0 | D6: 0 | E6: 0 | F6: =COUNTA('3'!C$3:C$5000) -> 0 | G6: =COUNTA('3'!D$3:D$5000) -> 0
A7: 4 | B7: Предприятия по переработке отходов | C7: =COUNTA('4'!C$3:F$5000) -> 0 | D7: 0 | E7: 0 | F7: =COUNTA('4'!C$3:C$5000) -> 0 | G7: =COUNTA('4'!D$3:D$5000) -> 0
A8: 5 | B8: Территория | C8: =COUNTA('5'!C$3:F$5000) -> 0 | D8: 0 | E8: 0 | F8: =COUNTA('5'!C$3:C$5000) -> 0 | G8: =COUNTA('5'!D$3:D$5000) -> 0
A9: 6 | B9: Сельское хозяйство | C9: =COUNTA('6'!C$3:F$5000) -> 200 | D9: 0 | E9: 0 | F9: =COUNTA('6'!C$3:C$5000) -> 200 | G9: =COUNTA('6'!D$3:D$5000) -> 0
A10: 7 | B10: Коммунальная сфера | C10: =COUNTA('7'!C$3:F$5000) -> 0 | D10: 0 | E10: 0 | F10: =COUNTA('7'!C$3:C$5000) -> 0 | G10: =COUNTA('7'!D$3:D$5000) -> 0
A11: 8 | B11: Инвестиции в основной капитал | C11: =COUNTA('8'!C$3:F$5000) -> 0 | D11: 0 | E11: 0 | F11: =COUNTA('8'!C$3:C$5000) -> 0 | G11: =COUNTA('8'!D$3:D$5000) -> 0
A12: 9 | B12: Социальная поддержка по оплате жилых помещений и коммунальных услуг | C12: =COUNTA('9'!C$3:F$5000) -> 4 | D12: 0 | E12: 0 | F12: =COUNTA('9'!C$3:C$5000) -> 4 | G12: =COUNTA('9'!D$3:D$5000) -> 0
A13: 10 | B13: Бухгалтерская отчетность | C13: =COUNTA('10'!C$3:F$5000) -> 0 | D13: 0 | E13: 0 | F13: =COUNTA('10'!C$3:C$5000) -> 0 | G13: =COUNTA('10'!D$3:D$5000) -> 0
A14: 11 | B14: Коллективные средства размещения | C14: =COUNTA('11'!C$3:F$5000) -> 0 | D14: 0 | E14: 0 | F14: =COUNTA('11'!C$3:C$5000) -> 0 | G14: =COUNTA('11'!D$3:D$5000) -> 0
A15: 12 | B15: Почтовая и телефонная связь | C15: =COUNTA('12'!C$3:F$5000) -> 0 | D15: 0 | E15: 0 | F15: =COUNTA('12'!C$3:C$5000) -> 0 | G15: =COUNTA('12'!D$3:D$5000) -> 0
A16: 13 | B16: Население | C16: =COUNTA('13'!C$3:F$5000) -> 2 | D16: 0 | E16: 0 | F16: =COUNTA('13'!C$3:C$5000) -> 2 | G16: =COUNTA('13'!D$3:D$5000) -> 0
A17: 14 | B17: Занятость и заработная плата | C17: =COUNTA('14'!C$3:F$5000) -> 129 | D17: 0 | E17: 0 | F17: =COUNTA('14'!C$3:C$5000) -> 129 | G17: =COUNTA('14'!D$3:D$5000) -> 0
A18: 15 | B18: Здравоохранение | C18: =COUNTA('15'!C$3:F$5000) -> 0 | D18: 0 | E18: 0 | F18: =COUNTA('15'!C$3:C$5000) -> 0 | G18: =COUNTA('15'!D$3:D$5000) -> 0
A19: 16 | B19: Образование | C19: =COUNTA('16'!C$3:F$5000) -> 0 | D19: 0 | E19: 0 | F19: =COUNTA('16'!C$3:C$5000) -> 0 | G19: =COUNTA('16'!D$3:D$5000) -> 0
A20: 17 | B20: Охрана окружающей среды | C20: =COUNTA('17'!C$3:F$5000) -> 0 | D20: 0 | E20: 0 | F20: =COUNTA('17'!C$3:C$5000) -> 0 | G20: =COUNTA('17'!D$3:D$5000) -> 0
A21: 18 | B21: Основные фонды организаций (без субъектов малого предпринимательства) | C21: =COUNTA('18'!C$3:F$5000) -> 0 | D21: 0 | E21: 0 | F21: =COUNTA('18'!C$3:C$5000) -> 0 | G21: =COUNTA('18'!D$3:D$5000) -> 0
A22: 19 | B22: Строительство жилья | C22: =COUNTA('19'!C$3:F$5000) -> 0 | D22: 0 | E22: 0 | F22: =COUNTA('19'!C$3:C$5000) -> 0 | G22: =COUNTA('19'!D$3:D$5000) -> 0
A23: 20 | B23: Деятельность предприятий | C23: =COUNTA('20'!C$3:F$5000) -> 38 | D23: 0 | E23: 0 | F23: =COUNTA('20'!C$3:C$5000) -> 36 | G23: =COUNTA('20'!D$3:D$5000) -> 2
A24: 21 | B24: Показатели для оценки эффективности деятельности органов местного самоуправления городских округов и муниципальных районов | C24: =COUNTA('21'!C$3:F$5000) -> 1 | D24: 0 | E24: 0 | F24: =COUNTA('21'!C$3:C$5000) -> 1 | G24: =COUNTA('21'!D$3:D$5000) -> 0
A25: 22 | B25: Финансовая деятельность | C25: =COUNTA('22'!C$3:F$5000) -> 30 | D25: 0 | E25: 0 | F25: =COUNTA('22'!C$3:C$5000) -> 30 | G25: =COUNTA('22'!D$3:D$5000) -> 0
A26: 23 | B26: Сведения о выданных разрешениях и уведомлениях на строительство и на ввод объектов в эксплуатацию | C26: =COUNTA('23'!C$3:F$5000) -> 0 | D26: 0 | E26: 0 | F26: =COUNTA('23'!C$3:C$5000) -> 0 | G26: =COUNTA('23'!D$3:D$5000) -> 0

Sheet 1
A1: Платные услуги населению

Sheet 2
A1: Розничная торговля и общественное питание
A2: Показатели | B2: Ед, измерения | C2: 2025 | D2: 2026
A3: Оборот розничной торговли (без субъектов малого предпринимательства) (с 2017 г,)
A4: Всего по обследуемым видам экономической деятельности
A5: январь-март | B5: тысяча рублей | C5: 614938.1
A6: январь-июнь | B6: тысяча рублей | C6: 1311511.4
A7: январь-сентябрь | B7: тысяча рублей | C7: 2050626
A8: январь-декабрь | B8: тысяча рублей | C8: 2856568.7
A9: Торговля розничная, кроме торговли автотранспортными средствами и мотоциклами
A10: январь-март | B10: тысяча рублей | C10: 601423.5
A11: январь-июнь | B11: тысяча рублей | C11: 1286207
A12: январь-сентябрь | B12: тысяча рублей | C12: 2005959.9
A13: январь-декабрь | B13: тысяча рублей | C13: 2756604.6
A14: Торговля розничная в неспециализированных магазинах
A15: январь-март | B15: тысяча рублей | C15: 413398.6
A16: январь-июнь | B16: тысяча рублей | C16: 875865.6
A17: январь-сентябрь | B17: тысяча рублей | C17: 1321273.5
A18: январь-декабрь | B18: тысяча рублей | C18: 1789975.4
A19: Торговля розничная пищевыми продуктами, напитками и табачными изделиями в специализированных магазинах
A20: январь-март | B20: тысяча рублей | C20: 83263
A21: январь-июнь | B21: тысяча рублей | C21: 185393
A22: январь-сентябрь | B22: тысяча рублей | C22: 292554
A23: январь-декабрь | B23: тысяча рублей | C23: 400167
A24: Оборот общественного питания (без субъектов малого предпринимательства) (с 2017 г,)
A25: Всего по обследуемым видам экономической деятельности
A26: январь-март | B26: тысяча рублей | C26: 2120
A27: январь-июнь | B27: тысяча рублей | C27: 5730
A28: Количество объектов розничной торговли и общественного питания
A29: магазины | B29: единица | C29: 184
A30: павильоны | B30: единица | C30: 7
A31: киоски | B31: единица | C31: 6
A32: аптечные организации | B32: единица | C32: 11
A33: общедоступные столовые, закусочные | B33: единица | C33: 2
A34: столовые учебных заведений, организаций, промышленных предприятий | B34: единица | C34: 22
A35: супермаркеты | B35: единица | C35: 11
A36: рестораны, кафе, бары | B36: единица | C36: 10
A37: минимаркеты | B37: единица | C37: 126
A38: универсальные и специализированные продовольственные | B38: единица | C38: 5
A39: универсальные и специализированные непродовольственные | B39: единица | C39: 42
A40: Число ярмарок
...

Sheet 3
A1: Спорт

Sheet 4
A1: Предприятия по переработке отходов

Sheet 5
A1: Территория

Sheet 6
A1: Сельское хозяйство
A2: Показатели | B2: Ед, измерения | C2: 2025 | D2: 2026
A3: Реализация продукции сельскохозяйственными организациями (с 20217 г,)
A4: Скот и птица (в живом весе)
A5: центнер | B5: - | C5: 20373.6
A6: Зерно злаковых и бобовых культур
A7: центнер | B7: - | C7: 942381.39
A8: Молоко от всех видов животных
A9: центнер | B9: - | C9: 704511.23
A10: Пшеница
A11: центнер | B11: - | C11: 649124.55
A12: Крупный рогатый скот
A13: центнер | B13: - | C13: 20353.6
A14: Семена и плоды масличных культуры
A15: центнер | B15: - | C15: 2209.28
A16: Посевные площади сельскохозяйственных культур в хозяйствах всех категорий
A17: Хозяйства всех категорий
A18: Вся посевная площадь | B18: гектар | C18: 74518.61
A19: Зерновые и зернобобовые культуры - всего | B19: гектар | C19: 52178.45
A20: Пшеница яровая | B20: гектар | C20: 35675.5
A21: Ячмень яровой | B21: гектар | C21: 1996
A22: Овес | B22: гектар | C22: 9335.35
A23: Зернобобовые культуры - всего | B23: гектар | C23: 5171.6
A24: Горох | B24: гектар | C24: 5171.6
A25: Технические культуры - всего | B25: гектар | C25: 3025
A26: Лен-кудряш (масличный) | B26: гектар | C26: 1859
A27: Рапс яровой (кольза) | B27: гектар | C27: 1166
A28: Картофель | B28: гектар | C28: 441.8
A29: Овощи (без высадков) | B29: гектар | C29: 52.36
A30: Капуста всякая | B30: гектар | C30: 01,09,1941
A31: Огурцы | B31: гектар | C31: 01,04,1984
A32: Помидоры | B32: гектар | C32: 01,10,2022
A33: Свекла столовая | B33: гектар | C33: 01,02,1996
A34: Морковь столовая | B34: гектар | C34: 05,05,2026
A35: Лук репчатый | B35: гектар | C35: 01,07,1987
A36: Чеснок | B36: гектар | C36: 01,02,1993
A37: Горох овощной (зеленый горошек) | B37: гектар | C37: 0.42
A38: Тыква | B38: гектар | C38: 01,02,1958
A39: Кабачки | B39: гектар | C39: 04,03,2026
A40: Кормовые культуры - всего | B40: гектар | C40: 18821
...

Sheet 7
A1: Коммунальная сфера

Sheet 8
A1: Инвестиции в основной капитал

Sheet 9
A1: Социальная поддержка по оплате жилых помещений и коммунальных услуг
A2: Показатели | B2: Ед, измерения | C2: 2025 | D2: 2026
A3: Число семей, получавших субсидии на оплату жилого помещения и коммунальных услуг на конец отчетного периода
A4: январь-март | B4: единица | C4: 109
A5: Сумма начисленных субсидий населению на оплату жилого помещения и коммунальных услуг за отчетный период (2014, 2015 рубли)
A6: январь-март | B6: тысяча рублей | C6: 482.3
A7: Численность граждан, пользующихся социальной поддержкой (льготами) по оплате жилого помещения и коммунальных услуг на конец отчетного периода
A8: январь-март | B8: единица | C8: 4980
A9: Объем средств, предусмотренных на предоставление социальной поддержки по оплате жилого помещения и коммунальных услуг за отчетный период (2014, 2015 - рубли)
A10: январь-март | B10: тысяча рублей | C10: 22354.3

Sheet 10
A1: Бухгалтерская отчетность

Sheet 11
A1: Коллективные средства размещения

Sheet 12
A1: Почтовая и телефонная связь

Sheet 13
A1: Население
A2: Показатели | B2: Ед, измерения | C2: 2025 | D2: 2026
A3: Оценка численности городского и сельского населения на 1 января текущего года
A4: Все население
A5: на 1 января | B5: человек | C5: 23438
A6: Сельское население
A7: на 1 января | B7: человек | C7: 23438

Sheet 14
A1: Занятость и заработная плата
A2: Показатели | B2: Ед, измерения | C2: 2025 | D2: 2026
A3: Среднесписочная численность работников организаций (без субъектов малого предпринимательства) с 2017 г,
A4: Всего по обследуемым видам экономической деятельности
A5: январь-март | B5: человек | C5: 4343
A6: январь-июнь | B6: человек | C6: 4367
A7: январь-сентябрь | B7: человек | C7: 4369
A8: январь-декабрь | B8: человек | C8: 4353
A9: Раздел А Сельское, лесное хозяйство, охота, рыболовство и рыбоводство
A10: январь-март | B10: человек | C10: 1446
A11: январь-июнь | B11: человек | C11: 1464
A12: январь-сентябрь | B12: человек | C12: 1456
A13: январь-декабрь | B13: человек | C13: 1444
A14: Раздел D Обеспечение электрической энергией, газом и паром; кондиционирование воздуха
A15: январь-март | B15: человек | C15: 120
A16: январь-июнь | B16: человек | C16: 119
A17: январь-сентябрь | B17: человек | C17: 119
A18: январь-декабрь | B18: человек | C18: 120
A19: Раздел G Торговля оптовая и розничная; ремонт автотранспортных средств и мотоциклов
A20: январь-март | B20: человек | C20: 229
A21: январь-июнь | B21: человек | C21: 233
A22: январь-сентябрь | B22: человек | C22: 234
A23: январь-декабрь | B23: человек | C23: 230
A24: Раздел Н Транспортировка и хранение
A25: январь-март | B25: человек | C25: 425
A26: январь-июнь | B26: человек | C26: 415
A27: январь-сентябрь | B27: человек | C27: 409
A28: январь-декабрь | B28: человек | C28: 404
A29: Раздел K Деятельность финансовая и страховая
A30: январь-март | B30: человек | C30: 17
A31: январь-июнь | B31: человек | C31: 17
A32: январь-сентябрь | B32: человек | C32: 17
A33: январь-декабрь | B33: человек | C33: 17
A34: Раздел M Деятельность профессиональная, научная и техническая
A35: январь-март | B35: человек | C35: 61
A36: январь-июнь | B36: человек | C36: 61
A37: январь-сентябрь | B37: человек | C37: 60
A38: январь-декабрь | B38: человек | C38: 59
A39: Раздел O Государственное управление и обеспечение военной безопасности; социальное обеспечение
A40: январь-март | B40: человек | C40: 478
...

Sheet 15
A1: Здравоохранение

Sheet 16
A1: Образование

Sheet 17
A1: Охрана окружающей среды

Sheet 18
A1: Основные фонды организаций (без субъектов малого предпринимательства)

Sheet 19
A1: Строительство жилья

Sheet 20
A1: Деятельность предприятий
A2: Показатели | B2: Ед, измерения | C2: 2025 | D2: 2026
A3: Отгружено товаров собственного производства, выполнено работ и услуг собственными силами (без субъектов малого предпринимательства) (с 2017 г,)
A4: Всего по обследуемым видам экономической деятельности
A5: январь-март | B5: тысяча рублей | C5: 3570973.2
A6: январь-июнь | B6: тысяча рублей | C6: 6974180.2
A7: январь-сентябрь | B7: тысяча рублей | C7: 10162741
A8: январь-декабрь | B8: тысяча рублей | C8: 14412270
A9: Раздел А Сельское, лесное хозяйство, охота, рыболовство и рыбоводство
A10: январь-март | B10: тысяча рублей | C10: 3046705.8
A11: январь-июнь | B11: тысяча рублей | C11: 6005557.3
A12: январь-сентябрь | B12: тысяча рублей | C12: 8722230.7
A13: январь-декабрь | B13: тысяча рублей | C13: 12293252
A14: Раздел G Торговля оптовая и розничная; ремонт автотранспортных средств и мотоциклов
A15: январь-март | B15: тысяча рублей | C15: 6783.9
A16: январь-июнь | B16: тысяча рублей | C16: 16494.2
A17: январь-сентябрь | B17: тысяча рублей | C17: 26888.7
A18: январь-декабрь | B18: тысяча рублей | C18: 35687.3
A19: Раздел P Образование
A20: январь-март | B20: тысяча рублей | C20: 4622.8
A21: январь-июнь | B21: тысяча рублей | C21: 9247.9
A22: январь-сентябрь | B22: тысяча рублей | C22: 11951.8
A23: январь-декабрь | B23: тысяча рублей | C23: 19698
A24: Продано товаров несобственного производства (без субъектов малого предпринимательства) (с 2017 г,)
A25: Всего по обследуемым видам экономической деятельности
A26: январь-март | B26: тысяча рублей | C26: 707979.2
A27: январь-июнь | B27: тысяча рублей | C27: 2127092.8
A28: январь-сентябрь | B28: тысяча рублей | C28: 5198728.1
A29: январь-декабрь | B29: тысяча рублей | C29: 8300724.2
A30: Раздел G Торговля оптовая и розничная; ремонт автотранспортных средств и мотоциклов
A31: январь-март | B31: тысяча рублей | C31: 490378.3
A32: январь-июнь | B32: тысяча рублей | C32: 1765988.7
A33: январь-сентябрь | B33: тысяча рублей | C33: 4743473.9
A34: январь-декабрь | B34: тысяча рублей | C34: 7682718.7
A35: Отгружено товаров собственного производства, выполнено работ и услуг собственными силами (без субъектов малого предпринимательства), средняя численность работников которых превышает 15 человек, по фактическим видам экономической деятельности (с 2017 года)
A36: Раздел C Обрабатывающие производства
A37: январь-март | B37: тысяча рублей | C37: 2161126.7
A38: январь-июнь | B38: тысяча рублей | C38: 4363778.4
A39: январь-сентябрь | B39: тысяча рублей | C39: 6369857.8
A40: январь-декабрь | B40: тысяча рублей | C40: 8588620.3
...

Sheet 21
A1: Показатели для оценки эффективности деятельности органов местного самоуправления городских округов и муниципальных районов
A2: Показатели | B2: Ед, измерения | C2: 2025 | D2: 2026
A3: Доля прибыльных сельскохозяйственных организаций в общем их числе
A4: Сельское хозяйство (без вспомогательной деятельности, оказания услуг)
A5: Всего | B5: процент | C5: 50

Sheet 22
A1: Финансовая деятельность
A2: Показатели | B2: Ед, измерения | C2: 2025 | D2: 2026
A3: Прибыль (убыток) до налогообложения отчетного периода (с 2017 года)
A4: Всего по обследуемым видам экономической деятельности
A5: Всего | B5: тысяча рублей | C5: -155762
A6: Прибыль (убыток) до налогообложения прошлого года (по уточненным данным) (с 2017 года)
A7: Всего по обследуемым видам экономической деятельности
A8: Всего | B8: тысяча рублей | C8: -230238
A9: Дебиторская задолженность (с 2017 года)
A10: Всего по обследуемым видам экономической деятельности
A11: Всего | B11: тысяча рублей | C11: 415651
A12: Задолженность покупателей и заказчиков за товары, работы и услуги из общей суммы дебиторской задолженности (с 2017 года)
A13: Всего по обследуемым видам экономической деятельности
A14: Всего | B14: тысяча рублей | C14: 342740
A15: Кредиторская задолженность (с 2017 года)
A16: Всего по обследуемым видам экономической деятельности
A17: Всего | B17: тысяча рублей | C17: 1234583
A18: Задолженность по платежам в бюджет из общей суммы кредиторской задолженности (с 2017 года)
A19: Всего по обследуемым видам экономической деятельности
A20: Всего | B20: тысяча рублей | C20: 32223
A21: Задолженность по взносам на обязательное социальное страхование, обязательное пенсионное обеспечение, обязательное медицинское страхование из общей суммы кредиторской задолженности крупных и средних предприятий и организаций
A22: Всего по обследуемым видам экономической деятельности
A23: Всего | B23: тысяча рублей | C23: 12861
A24: Задолженность поставщикам и подрядчикам за товары, работы и услуги из общей суммы кредиторской задолженности (с 2017 года)
A25: Всего по обследуемым видам экономической деятельности
A26: Всего | B26: тысяча рублей | C26: 1022479
A27: Количество организаций представивших отчет (с 2017 года)
A28: Всего по обследуемым видам экономической деятельности
A29: Всего | B29: единица | C29: 5
A30: Количество прибыльных организаций (с 2017 года)
A31: Всего по обследуемым видам экономической деятельности
A32: Всего | B32: единица | C32: 4
A33: Финансовый результат прибыльных организаций (с 2017 года)
A34: Всего по обследуемым видам экономической деятельности
A35: Всего | B35: тысяча рублей | C35: 66246
A36: Удельный вес убыточных организаций в общем числе организаций (с 2017 года)
A37: Всего по обследуемым видам экономической деятельности
A38: Всего | B38: процент | C38: 20
A39: Раздел А Сельское, лесное хозяйство, охота, рыболовство и рыбоводство
A40: Всего | B40: процент | C40: 50
...

Sheet 23
A1: Сведения о выданных разрешениях и уведомлениях на строительство и на ввод объектов в эксплуатацию
